{
    "registryname": "chrono_automator_tier1",
    "localizedname": "Chrono Automator Tier 1",
    "requires-blueprint": true,
        "parts": [
            {
                "x": -1,
                "y": 0,
                "z": 0,
                "elements": [
                    "modularmachinery:blockcasing@0"
                ]
            },
            {
                "x": -1,
                "y": 0,
                "z": 1,
                "elements": [
                    "modularmachinery:blockoutputbus"
                ]
            },
            {
                "x": 0,
                "y": 2,
                "z": 2,
                "elements": [
                    "modularmachinery:blockcasing@0"
                ]
            },
            {
                "x": 1,
                "y": 2,
                "z": 1,
                "elements": [
                    "modularmachinery:blockcasing@0"
                ]
            },
            {
                "x": 0,
                "y": 0,
                "z": 1,
                "elements": [
                    "modularmachinery:blockcasing@0"
                ]
            },
            {
                "x": 1,
                "y": 0,
                "z": 0,
                "elements": [
                    "modularmachinery:blockcasing@0"
                ]
            },
            {
                "x": -1,
                "y": 0,
                "z": 2,
                "elements": [
                    "modularmachinery:blockcasing@0"
                ]
            },
            {
                "x": 1,
                "y": 2,
                "z": 2,
                "elements": [
                    "modularmachinery:blockcasing@0"
                ]
            },
            {
                "x": 1,
                "y": 0,
                "z": 1,
                "elements": [
                    "modularmachinery:blockinputbus"
                ]
            },
            {
                "x": 0,
                "y": 0,
                "z": 2,
                "elements": [
                    "modularmachinery:blockenergyinputhatch"
                ]
            },
            {
                "x": 1,
                "y": 0,
                "z": 2,
                "elements": [
                    "modularmachinery:blockcasing@0"
                ]
            },
            {
                "x": 0,
                "y": 3,
                "z": 0,
                "elements": [
                    "minecraft:iron_bars@0"
                ]
            },
            {
                "x": -1,
                "y": 3,
                "z": 1,
                "elements": [
                    "minecraft:iron_bars@0"
                ]
            },
            {
                "x": 0,
                "y": 3,
                "z": 1,
                "elements": [
                    "environmentaltech:lightning_rod_insulated@0"
                ]
            },
            {
                "x": -1,
                "y": 1,
                "z": 0,
                "elements": [
                    "modularmachinery:blockcasing@0"
                ]
            },
            {
                "x": 0,
                "y": 3,
                "z": 2,
                "elements": [
                    "minecraft:iron_bars@0"
                ]
            },
            {
                "x": 1,
                "y": 3,
                "z": 1,
                "elements": [
                    "minecraft:iron_bars@0"
                ]
            },
            {
                "x": 0,
                "y": 1,
                "z": 0,
                "elements": [
                    "thermalfoundation:glass_alloy@5"
                ]
            },
            {
                "x": -1,
                "y": 1,
                "z": 1,
                "elements": [
                    "thermalfoundation:glass_alloy@5"
                ]
            },
            {
                "x": 0,
                "y": 1,
                "z": 1,
                "elements": [
                    "parachronology:displacer@0"
                ]
            },
            {
                "x": 1,
                "y": 1,
                "z": 0,
                "elements": [
                    "modularmachinery:blockcasing@0"
                ]
            },
            {
                "x": -1,
                "y": 1,
                "z": 2,
                "elements": [
                    "modularmachinery:blockcasing@0"
                ]
            },
            {
                "x": 0,
                "y": 1,
                "z": 2,
                "elements": [
                    "thermalfoundation:glass_alloy@5"
                ]
            },
            {
                "x": 1,
                "y": 1,
                "z": 1,
                "elements": [
                    "thermalfoundation:glass_alloy@5"
                ]
            },
            {
                "x": 1,
                "y": 1,
                "z": 2,
                "elements": [
                    "modularmachinery:blockcasing@0"
                ]
            },
            {
                "x": -1,
                "y": 4,
                "z": 1,
                "elements": [
                    "minecraft:iron_bars@0"
                ]
            },
            {
                "x": 0,
                "y": 4,
                "z": 0,
                "elements": [
                    "minecraft:iron_bars@0"
                ]
            },
            {
                "x": -1,
                "y": 2,
                "z": 0,
                "elements": [
                    "modularmachinery:blockcasing@0"
                ]
            },
            {
                "x": 0,
                "y": 4,
                "z": 1,
                "elements": [
                    "environmentaltech:lightning_rod_insulated@0"
                ]
            },
            {
                "x": -1,
                "y": 2,
                "z": 1,
                "elements": [
                    "modularmachinery:blockcasing@0"
                ]
            },
            {
                "x": 0,
                "y": 4,
                "z": 2,
                "elements": [
                    "minecraft:iron_bars@0"
                ]
            },
            {
                "x": 1,
                "y": 4,
                "z": 1,
                "elements": [
                    "minecraft:iron_bars@0"
                ]
            },
            {
                "x": 0,
                "y": 2,
                "z": 0,
                "elements": [
                    "modularmachinery:blockcasing@0"
                ]
            },
            {
                "x": -1,
                "y": 2,
                "z": 2,
                "elements": [
                    "modularmachinery:blockcasing@0"
                ]
            },
            {
                "x": 0,
                "y": 2,
                "z": 1,
                "elements": [
                    "extrautils2:interactionproxy@0"
                ]
            },
            {
                "x": 1,
                "y": 2,
                "z": 0,
                "elements": [
                    "modularmachinery:blockcasing@0"
                ]
            }
        ]
    }